<?xml version='1.0'?>
<sdf version="1.6">
  <model name="assembly5">
    <link name="chassis">
      <pose frame="">0 0 0 0 0 0</pose>
      <inertial>
        <mass>13.741</mass>
        <pose frame="">0.269694 0.006877 0.146243 0 -0 0</pose>
        <inertia>
          <ixx>0.664203</ixx>
          <ixy>-0.011219</ixy>
          <ixz>-0.006052</ixz>
          <iyy>0.604736</iyy>
          <iyz>0.002064</iyz>
          <izz>1.054715</izz>
        </inertia>
      </inertial>
      <visual name="visual">
        <pose frame="">0 0 0.017 1.5708 0 -1.5708</pose>
        <geometry>
          <mesh>
            <uri>model://assembly5/meshes/Assembly5.stl</uri>
            <scale>1 1 1</scale>
          </mesh>
        </geometry>
      </visual>
      <collision name="collision">
        <pose frame="">0.3 0 0.1405 0 -0 0</pose>
        <geometry>
          <box>
            <size>0.6 0.6 0.247</size>
          </box>
        </geometry>
      </collision>
      <collision name="caster1_collision">
        <pose>0.5635 0.2635 0.024118 0 -0 0</pose>
        <geometry>
          <sphere>
            <radius>0.024118</radius>
          </sphere>
        </geometry>
        <surface>
          <friction>
            <ode>
              <mu>0</mu>
              <mu2>0</mu2>
              <slip1>1.0</slip1>
              <slip2>1.0</slip2>
            </ode>
          </friction>
        </surface>
      </collision>
      <collision name="caster2_collision">
        <pose>0.5635 -0.2635 0.024118 0 -0 0</pose>
        <geometry>
          <sphere>
            <radius>0.024118</radius>
          </sphere>
        </geometry>
        <surface>
          <friction>
            <ode>
              <mu>0</mu>
              <mu2>0</mu2>
              <slip1>1.0</slip1>
              <slip2>1.0</slip2>
            </ode>
          </friction>
        </surface>
      </collision>
    </link>
    <link name="left_wheel">
      <pose frame="">0.125 0.265 0.1 0 -0 0</pose>
      <inertial>
        <mass>1.79</mass>
      </inertial>
      <visual name="visual">
        <pose frame="">0 0 0 1.5708 -0 -1.5708</pose>
        <geometry>
          <mesh>
            <uri>model://assembly5/meshes/Wheel.stl</uri>
            <scale>1 1 1</scale>
          </mesh>
        </geometry>
      </visual>
      <collision name="collision">
        <pose frame="">0 0 0 1.5708 -0 0</pose>
        <geometry>
          <cylinder>
            <radius>0.1</radius>
            <length>0.05</length>
          </cylinder>
        </geometry>
        <surface>
          <friction>
            <ode>
              <mu>1</mu>
              <mu2>1</mu2>
              <slip1>0</slip1>
              <slip2>0</slip2>
            </ode>
          </friction>
        </surface>
      </collision>
    </link>
    <link name="right_wheel">
      <pose frame="">0.125 -0.265 0.1 0 -0 0</pose>
      <inertial>
        <mass>1.79</mass>
      </inertial>
      <visual name="visual">
        <pose frame="">0 0 0 1.5708 -0 1.5708</pose>
        <geometry>
          <mesh>
            <uri>model://assembly5/meshes/Wheel.stl</uri>
            <scale>1 1 1</scale>
          </mesh>
        </geometry>
      </visual>
      <collision name="collision">
        <pose frame="">0 0 0 1.5708 -0 0</pose>
        <geometry>
          <cylinder>
            <radius>0.1</radius>
            <length>0.05</length>
          </cylinder>
        </geometry>
        <surface>
          <friction>
            <ode>
              <mu>1</mu>
              <mu2>1</mu2>
              <slip1>0</slip1>
              <slip2>0</slip2>
            </ode>
          </friction>
        </surface>
      </collision>
    </link>
    <joint name="left_wheel_hinge" type="revolute">
      <parent>chassis</parent>
      <child>left_wheel</child>
      <pose frame="">0 0 0 0 -0 0</pose>
      <axis>
        <xyz>0 1 0</xyz>
      </axis>
    </joint>
    <joint name="right_wheel_hinge" type="revolute">
      <parent>chassis</parent>
      <child>right_wheel</child>
      <pose frame="">0 0 0 0 -0 0</pose>
      <axis>
        <xyz>0 1 0</xyz>
      </axis>
    </joint>

    <plugin filename="libgazebo_wheel_encoder.so" name="wheel_encoder">
      <updateRate>20</updateRate>
      <leftJoint>left_wheel_hinge</leftJoint>
      <rightJoint>right_wheel_hinge</rightJoint>
    </plugin>

    <plugin filename="libgazebo_ros_diff_drive.so" name="differential_drive_controller">
      <robotBaseFrame>chassis</robotBaseFrame>
      <legacyMode>false</legacyMode>
      <alwaysOn>true</alwaysOn>
      <updateRate>20</updateRate>
      <leftJoint>left_wheel_hinge</leftJoint>
      <rightJoint>right_wheel_hinge</rightJoint>
      <wheelSeparation>0.518</wheelSeparation>
      <wheelDiameter>0.2</wheelDiameter>
      <torque>200</torque>
      <commandTopic>/cmd_vel</commandTopic>
    </plugin>
  </model>
</sdf>
